<mujoco model="panda">
  <compiler angle="radian" assetdir="assets" autolimits="true"/>

  <option integrator="implicitfast"/>

  <default>
    <default class="panda">
      <material specular="0.5" shininess="0.25"/>
      <joint armature="0.1" damping="1" axis="0 0 1" range="-2.8973 2.8973"/>
      <motor ctrlrange="-87 87" forcerange="-87 87"/>
      <default class="finger">
        <joint axis="0 1 0" type="slide" range="0 0.04"/>
      </default>

      <default class="visual">
        <geom type="mesh" contype="0" conaffinity="0" group="2"/>
      </default>
      <default class="collision">
        <geom type="mesh" group="3"/>
        <default class="fingertip_pad_collision_1">
          <geom type="box" size="0.0085 0.004 0.0085" pos="0 0.0055 0.0445"/>
        </default>
        <default class="fingertip_pad_collision_2">
          <geom type="box" size="0.003 0.002 0.003" pos="0.0055 0.002 0.05"/>
        </default>
        <default class="fingertip_pad_collision_3">
          <geom type="box" size="0.003 0.002 0.003" pos="-0.0055 0.002 0.05"/>
        </default>
        <default class="fingertip_pad_collision_4">
          <geom type="box" size="0.003 0.002 0.0035" pos="0.0055 0.002 0.0395"/>
        </default>
        <default class="fingertip_pad_collision_5">
          <geom type="box" size="0.003 0.002 0.0035" pos="-0.0055 0.002 0.0395"/>
        </default>
      </default>
    </default>
  </default>

  <asset>
    <texture builtin="gradient" height="256" rgb1=".9 .9 1." rgb2=".2 .3 .4" type="skybox" width="256"/>
    <texture name="texplane" file="light-gray-floor-tile.png" type="2d"/>
    <texture name="tex-ceramic" file="ceramic.png" type="cube"/>
    <texture name="tex-steel-brushed" file="steel-brushed.png" type="cube"/>
    <texture name="tex-light-gray-plaster" file="light-gray-plaster.png" type="2d"/>
    <texture name="textable" builtin="flat" height="512" width="512" rgb1="0.5 0.5 0.5" rgb2="0.5 0.5 0.5"/>

    <material name="floorplane" reflectance="0.01" shininess="0.0" specular="0.0" texrepeat="2 2" texture="texplane" texuniform="true"/>
    <material name="table_ceramic" reflectance="0.0" shininess="0.0" specular="0.2" texrepeat="1 1" texture="tex-ceramic"/>
    <material name="table_legs_metal" reflectance="0.8" shininess="0.8" texrepeat="1 1" texture="tex-steel-brushed"/>
    <material name="walls_mat" reflectance="0.0" shininess="0.1" specular="0.1" texrepeat="3 3" texture="tex-light-gray-plaster" texuniform="true"/>
    <material name="table_mat" texture="textable"/>

    <material class="panda" name="white" rgba="1 1 1 1"/>
    <material class="panda" name="off_white" rgba="0.901961 0.921569 0.929412 1"/>
    <material class="panda" name="black" rgba="0.25 0.25 0.25 1"/>
    <material class="panda" name="green" rgba="0 1 0 1"/>
    <material class="panda" name="light_blue" rgba="0.039216 0.541176 0.780392 1"/>

    <!-- Mount mesh -->
    <mesh name="mount_pedestal" file="pedestal.stl"/>

    <!-- Collision meshes -->
    <mesh name="link0_c" file="link0.stl"/>
    <mesh name="link1_c" file="link1.stl"/>
    <mesh name="link2_c" file="link2.stl"/>
    <mesh name="link3_c" file="link3.stl"/>
    <mesh name="link4_c" file="link4.stl"/>
    <mesh name="link5_c0" file="link5_collision_0.obj"/>
    <mesh name="link5_c1" file="link5_collision_1.obj"/>
    <mesh name="link5_c2" file="link5_collision_2.obj"/>
    <mesh name="link6_c" file="link6.stl"/>
    <mesh name="link7_c" file="link7.stl"/>
    <mesh name="hand_c" file="hand.stl"/>

    <!-- Visual meshes -->
    <mesh file="link0_0.obj"/>
    <mesh file="link0_1.obj"/>
    <mesh file="link0_2.obj"/>
    <mesh file="link0_3.obj"/>
    <mesh file="link0_4.obj"/>
    <mesh file="link0_5.obj"/>
    <mesh file="link0_7.obj"/>
    <mesh file="link0_8.obj"/>
    <mesh file="link0_9.obj"/>
    <mesh file="link0_10.obj"/>
    <mesh file="link0_11.obj"/>
    <mesh file="link1.obj"/>
    <mesh file="link2.obj"/>
    <mesh file="link3_0.obj"/>
    <mesh file="link3_1.obj"/>
    <mesh file="link3_2.obj"/>
    <mesh file="link3_3.obj"/>
    <mesh file="link4_0.obj"/>
    <mesh file="link4_1.obj"/>
    <mesh file="link4_2.obj"/>
    <mesh file="link4_3.obj"/>
    <mesh file="link5_0.obj"/>
    <mesh file="link5_1.obj"/>
    <mesh file="link5_2.obj"/>
    <mesh file="link6_0.obj"/>
    <mesh file="link6_1.obj"/>
    <mesh file="link6_2.obj"/>
    <mesh file="link6_3.obj"/>
    <mesh file="link6_4.obj"/>
    <mesh file="link6_5.obj"/>
    <mesh file="link6_6.obj"/>
    <mesh file="link6_7.obj"/>
    <mesh file="link6_8.obj"/>
    <mesh file="link6_9.obj"/>
    <mesh file="link6_10.obj"/>
    <mesh file="link6_11.obj"/>
    <mesh file="link6_12.obj"/>
    <mesh file="link6_13.obj"/>
    <mesh file="link6_14.obj"/>
    <mesh file="link6_15.obj"/>
    <mesh file="link6_16.obj"/>
    <mesh file="link7_0.obj"/>
    <mesh file="link7_1.obj"/>
    <mesh file="link7_2.obj"/>
    <mesh file="link7_3.obj"/>
    <mesh file="link7_4.obj"/>
    <mesh file="link7_5.obj"/>
    <mesh file="link7_6.obj"/>
    <mesh file="link7_7.obj"/>
    <mesh file="hand_0.obj"/>
    <mesh file="hand_1.obj"/>
    <mesh file="hand_2.obj"/>
    <mesh file="hand_3.obj"/>
    <mesh file="hand_4.obj"/>
    <mesh file="finger_0.obj"/>
    <mesh file="finger_1.obj"/>
  </asset>

  <worldbody>
    <light name="top" pos="1.0 1.0 1.5" dir="-0.2 -0.2 -1" specular="0.3 0.3 0.3" directional="true" castshadow="false" />

    <!-- Background -->
    <geom name="floor" pos="0.0 0.0 0.0" size="3 3 .125" type="plane" condim="3" group="1" material="floorplane"/>
    <geom name="wall_leftcorner_visual" pos="-1.25 2.25 1.5" quat="0.6532815 0.6532815 0.2705981 0.2705981" size="1.06 1.5 0.01" type="box" conaffinity="0" contype="0" group="1" material="walls_mat"/>
    <geom name="wall_rightcorner_visual" pos="-1.25 -2.25 1.5" quat="0.6532815 0.6532815 -0.2705981 -0.2705981" size="1.06 1.5 0.01" type="box" conaffinity="0" contype="0" group="1" material="walls_mat"/>
    <geom name="wall_left_visual" pos="1.25 3.0 1.5" quat="0.7071 0.7071 0 0" size="1.75 1.5 0.01" type="box" conaffinity="0" contype="0" group="1" material="walls_mat"/>
    <geom name="wall_right_visual" pos="1.25 -3.0 1.5" quat="0.7071 -0.7071 0 0" size="1.75 1.5 0.01" type="box" conaffinity="0" contype="0" group="1" material="walls_mat"/>
    <geom name="wall_rear_visual" pos="-2.0 0.0 1.5" quat="0.5 0.5 0.5 0.5" size="1.5 1.5 0.01" type="box" conaffinity="0" contype="0" group="1" material="walls_mat"/>
    <geom name="wall_front_visual" pos="3.0 0.0 1.5" quat="0.5 0.5 -0.5 -0.5" size="3 1.5 0.01" type="box" conaffinity="0" contype="0" group="1" material="walls_mat"/>

    <!-- Camera -->
    <camera mode="fixed" name="frontview" pos="1.6 0.0 1.45" quat="0.56 0.43 0.43 0.56" />
    <camera mode="fixed" name="birdview" pos="-0.2 0.0 3.0" quat="0.7071 0 0 0.7071" />
    <camera mode="fixed" name="agentview" pos="0.5 0.0 1.35" quat="0.653 0.271 0.271 0.653" />
    <camera mode="fixed" name="sideview" pos="0.0 1.6 1.2" quat="0 0 0.7071 0.7071" />
    <camera mode="fixed" name="targetview" pos="-0.5 0.0 1.35" quat="-0.653 -0.271 0.271 0.653" fovy="58" resolution="620 480"/>

    <!-- Table -->
    <body name="table" pos="0.0 0.0 0.775">
      <geom name="table_collision" pos="0 0 0" size="0.4 0.4 0.025" type="box" group="0" friction="1.0 0.005 0.0001" rgba="0.5 0.5 0 1"/>
      <geom name="table_visual" pos="0 0 0" size="0.4 0.4 0.025" type="box" conaffinity="0" contype="0" group="1" material="table_ceramic"/>
      <geom name="table_leg1_visual" pos="0.30000000000000004 0.30000000000000004 -0.3875" size="0.025 0.3875" type="cylinder" conaffinity="0" contype="0" group="1" material="table_legs_metal"/>
      <geom name="table_leg2_visual" pos="-0.30000000000000004 0.30000000000000004 -0.3875" size="0.025 0.3875" type="cylinder" conaffinity="0" contype="0" group="1" material="table_legs_metal"/>
      <geom name="table_leg3_visual" pos="-0.30000000000000004 -0.30000000000000004 -0.3875" size="0.025 0.3875" type="cylinder" conaffinity="0" contype="0" group="1" material="table_legs_metal"/>
      <geom name="table_leg4_visual" pos="0.30000000000000004 -0.30000000000000004 -0.3875" size="0.025 0.3875" type="cylinder" conaffinity="0" contype="0" group="1" material="table_legs_metal"/>
    </body>

    <!-- Object -->
    <body name="object" pos="0 0 0.85">
      <freejoint name="object"/>
      <geom name="object_collision" pos="0 0 0" size="0.04 0.05" type="cylinder" class="collision"/>
      <geom name="object_visual" pos="0 0 0" size="0.04 0.05" type="cylinder" rgba="1 0 0 1" class="visual"/>
    </body>

    <!-- Mount & Robot-->
    <body name="robot_fixed" pos="-0.6 0 0.75">
      <inertial mass="0" pos="0 0 0" diaginertia="0 0 0"/>

      <body name="mount_base" pos="0.0 0.0 0.01">
        <body name="mount0_controller_box" pos="0 0 0">
            <geom pos="-0.325 0 -0.23" size="0.11 0.2 0.265" type="box" rgba="0.5 0.5 0 1" group="0"/>
        </body>
        <body name="mount_pedestal_feet" pos="0 0 0">
            <geom pos="-0.1225 0 -0.608" size="0.385 0.35 0.155" type="box" rgba="0.5 0.5 0 1" group="0"/>
        </body>
        <body name="mount_torso" pos="0 0 0">
            <geom conaffinity="0" contype="0" pos="0 0 -0.05" size="0.05 0.05 0.05" type="box" rgba="0.2 0.2 0.2 1" group="1"/>
        </body>
        <body name="mount_pedestal" pos="0 0 0">
            <geom pos="-0.02 0 -0.225" rgba="0.5 0.5 0 1" size="0.18 0.225" type="cylinder" group="0"/>
        </body>
      </body>

      <body name="link0" childclass="panda">
        <inertial mass="0.629769" pos="-0.041018 -0.00014 0.049974"
          fullinertia="0.00315 0.00388 0.004285 8.2904e-7 0.00015 8.2299e-6"/>
        <geom mesh="link0_0" material="off_white" class="visual"/>
        <geom mesh="link0_1" material="black" class="visual"/>
        <geom mesh="link0_2" material="off_white" class="visual"/>
        <geom mesh="link0_3" material="black" class="visual"/>
        <geom mesh="link0_4" material="off_white" class="visual"/>
        <geom mesh="link0_5" material="black" class="visual"/>
        <geom mesh="link0_7" material="white" class="visual"/>
        <geom mesh="link0_8" material="white" class="visual"/>
        <geom mesh="link0_9" material="black" class="visual"/>
        <geom mesh="link0_10" material="off_white" class="visual"/>
        <geom mesh="link0_11" material="white" class="visual"/>
        <geom mesh="link0_c" class="collision"/>
        <body name="link1" pos="0 0 0.333">
          <inertial mass="4.970684" pos="0.003875 0.002081 -0.04762"
            fullinertia="0.70337 0.70661 0.0091170 -0.00013900 0.0067720 0.019169"/>
          <joint name="joint1"/>
          <geom material="white" mesh="link1" class="visual"/>
          <geom mesh="link1_c" class="collision"/>
          <body name="link2" quat="1 -1 0 0">
            <inertial mass="0.646926" pos="-0.003141 -0.02872 0.003495"
              fullinertia="0.0079620 2.8110e-2 2.5995e-2 -3.925e-3 1.0254e-2 7.04e-4"/>
            <joint name="joint2" range="-1.7628 1.7628"/>
            <geom material="white" mesh="link2" class="visual"/>
            <geom mesh="link2_c" class="collision"/>
            <body name="link3" pos="0 -0.316 0" quat="1 1 0 0">
              <joint name="joint3"/>
              <inertial mass="3.228604" pos="2.7518e-2 3.9252e-2 -6.6502e-2"
                fullinertia="3.7242e-2 3.6155e-2 1.083e-2 -4.761e-3 -1.1396e-2 -1.2805e-2"/>
              <geom mesh="link3_0" material="white" class="visual"/>
              <geom mesh="link3_1" material="white" class="visual"/>
              <geom mesh="link3_2" material="white" class="visual"/>
              <geom mesh="link3_3" material="black" class="visual"/>
              <geom mesh="link3_c" class="collision"/>
              <body name="link4" pos="0.0825 0 0" quat="1 1 0 0">
                <inertial mass="3.587895" pos="-5.317e-2 1.04419e-1 2.7454e-2"
                  fullinertia="2.5853e-2 1.9552e-2 2.8323e-2 7.796e-3 -1.332e-3 8.641e-3"/>
                <joint name="joint4" range="-3.0718 -0.0698"/>
                <geom mesh="link4_0" material="white" class="visual"/>
                <geom mesh="link4_1" material="white" class="visual"/>
                <geom mesh="link4_2" material="black" class="visual"/>
                <geom mesh="link4_3" material="white" class="visual"/>
                <geom mesh="link4_c" class="collision"/>
                <body name="link5" pos="-0.0825 0.384 0" quat="1 -1 0 0">
                  <inertial mass="1.225946" pos="-1.1953e-2 4.1065e-2 -3.8437e-2"
                    fullinertia="3.5549e-2 2.9474e-2 8.627e-3 -2.117e-3 -4.037e-3 2.29e-4"/>
                  <joint name="joint5"/>
                  <geom mesh="link5_0" material="black" class="visual"/>
                  <geom mesh="link5_1" material="white" class="visual"/>
                  <geom mesh="link5_2" material="white" class="visual"/>
                  <geom mesh="link5_c0" class="collision"/>
                  <geom mesh="link5_c1" class="collision"/>
                  <geom mesh="link5_c2" class="collision"/>
                  <body name="link6" quat="1 1 0 0">
                    <inertial mass="1.666555" pos="6.0149e-2 -1.4117e-2 -1.0517e-2"
                      fullinertia="1.964e-3 4.354e-3 5.433e-3 1.09e-4 -1.158e-3 3.41e-4"/>
                    <joint name="joint6" range="-0.0175 3.7525"/>
                    <geom mesh="link6_0" material="off_white" class="visual"/>
                    <geom mesh="link6_1" material="white" class="visual"/>
                    <geom mesh="link6_2" material="black" class="visual"/>
                    <geom mesh="link6_3" material="white" class="visual"/>
                    <geom mesh="link6_4" material="white" class="visual"/>
                    <geom mesh="link6_5" material="white" class="visual"/>
                    <geom mesh="link6_6" material="white" class="visual"/>
                    <geom mesh="link6_7" material="light_blue" class="visual"/>
                    <geom mesh="link6_8" material="light_blue" class="visual"/>
                    <geom mesh="link6_9" material="black" class="visual"/>
                    <geom mesh="link6_10" material="black" class="visual"/>
                    <geom mesh="link6_11" material="white" class="visual"/>
                    <geom mesh="link6_12" material="green" class="visual"/>
                    <geom mesh="link6_13" material="white" class="visual"/>
                    <geom mesh="link6_14" material="black" class="visual"/>
                    <geom mesh="link6_15" material="black" class="visual"/>
                    <geom mesh="link6_16" material="white" class="visual"/>
                    <geom mesh="link6_c" class="collision"/>
                    <body name="link7" pos="0.088 0 0" quat="1 1 0 0">
                      <inertial mass="7.35522e-01" pos="1.0517e-2 -4.252e-3 6.1597e-2"
                        fullinertia="1.2516e-2 1.0027e-2 4.815e-3 -4.28e-4 -1.196e-3 -7.41e-4"/>
                      <joint name="joint7"/>
                      <geom mesh="link7_0" material="white" class="visual"/>
                      <geom mesh="link7_1" material="black" class="visual"/>
                      <geom mesh="link7_2" material="black" class="visual"/>
                      <geom mesh="link7_3" material="black" class="visual"/>
                      <geom mesh="link7_4" material="black" class="visual"/>
                      <geom mesh="link7_5" material="black" class="visual"/>
                      <geom mesh="link7_6" material="black" class="visual"/>
                      <geom mesh="link7_7" material="white" class="visual"/>
                      <geom mesh="link7_c" class="collision"/>
                      <body name="hand" pos="0 0 0.107" quat="0.9238795 0 0 -0.3826834">
                        <body name="grasp_site" pos="0 0 0.105" />
                        <inertial mass="0.73" pos="-0.01 0 0.03" diaginertia="0.001 0.0025 0.0017"/>
                        <geom mesh="hand_0" material="off_white" class="visual"/>
                        <geom mesh="hand_1" material="black" class="visual"/>
                        <geom mesh="hand_2" material="black" class="visual"/>
                        <geom mesh="hand_3" material="white" class="visual"/>
                        <geom mesh="hand_4" material="off_white" class="visual"/>
                        <geom mesh="hand_c" class="collision"/>
                        <body name="left_finger" pos="0 0 0.0584">
                          <inertial mass="0.015" pos="0 0 0" diaginertia="2.375e-6 2.375e-6 7.5e-7"/>
                          <joint name="finger_joint1" class="finger"/>
                          <geom mesh="finger_0" material="off_white" class="visual"/>
                          <geom mesh="finger_1" material="black" class="visual"/>
                          <geom mesh="finger_0" class="collision"/>
                          <geom class="fingertip_pad_collision_1"/>
                          <geom class="fingertip_pad_collision_2"/>
                          <geom class="fingertip_pad_collision_3"/>
                          <geom class="fingertip_pad_collision_4"/>
                          <geom class="fingertip_pad_collision_5"/>
                        </body>
                        <body name="right_finger" pos="0 0 0.0584" quat="0 0 0 1">
                          <inertial mass="0.015" pos="0 0 0" diaginertia="2.375e-6 2.375e-6 7.5e-7"/>
                          <joint name="finger_joint2" class="finger"/>
                          <geom mesh="finger_0" material="off_white" class="visual"/>
                          <geom mesh="finger_1" material="black" class="visual"/>
                          <geom mesh="finger_0" class="collision"/>
                          <geom class="fingertip_pad_collision_1"/>
                          <geom class="fingertip_pad_collision_2"/>
                          <geom class="fingertip_pad_collision_3"/>
                          <geom class="fingertip_pad_collision_4"/>
                          <geom class="fingertip_pad_collision_5"/>
                        </body>
                      </body>
                    </body>
                  </body>
                </body>
              </body>
            </body>
          </body>
        </body>
      </body>
    </body>
  </worldbody>

  <tendon>
    <fixed name="split">
      <joint joint="finger_joint1" coef="0.5"/>
      <joint joint="finger_joint2" coef="0.5"/>
    </fixed>
  </tendon>

  <contact>
    <exclude body1="left_finger" body2="right_finger"/>
  </contact>

  <equality>
    <joint joint1="finger_joint1" joint2="finger_joint2" solimp="0.95 0.99 0.001" solref="0.005 1"/>
  </equality>

  <actuator>
    <motor class="panda" name="actuator1" joint="joint1"/>
    <motor class="panda" name="actuator2" joint="joint2"/>
    <motor class="panda" name="actuator3" joint="joint3"/>
    <motor class="panda" name="actuator4" joint="joint4"/>
    <motor class="panda" name="actuator5" joint="joint5" ctrlrange="-12 12" forcerange="-12 12"/>
    <motor class="panda" name="actuator6" joint="joint6" ctrlrange="-12 12" forcerange="-12 12"/>
    <motor class="panda" name="actuator7" joint="joint7" ctrlrange="-12 12" forcerange="-12 12"/>
    <!-- Remap original ctrlrange (0, 0.04) to (0, 255): 0.04 * 100 / 255 = 0.01568627451 -->
    <general class="panda" name="actuator8" tendon="split" forcerange="-100 100" ctrlrange="0 255"
      gainprm="0.01568627451 0 0" biasprm="0 -100 -10"/>
  </actuator>

<keyframe>
    <key name="home" qpos="0 0 0.85 1 0 0 0 0 0 0 -1.57079 0 1.57079 -0.7853 0.04 0.04"/>
</keyframe>

</mujoco>
